Workbook

Sheet Variables 
A1: VARIABLES A UTILIZAR EN EL PLAN DE NEGOCIOS
A3: VARIABLES MACROECONOMICAS | B3: Año 1 | C3: Año 2
A4: Evolución del PBI
A5: Tasa de Inflación esperada
A6: Variación de la tasa de inflación en % | C6: =(1-(C5/B5)) -> #DIV/0!
A7: Tasa de Política Monetaria | C7: =+B7-(B7*C6) -> #DIV/0!
A8: Tasa de Captación de Ahorro | C8: =+B8-(B8*C7) -> #DIV/0!
A9: Tasa de Ayuda Económica | C9: =+B9-(B9*C8) -> #DIV/0!
A12: CAPTACION DE DEPOSITOS | B12: Parámetros
A13: Porcentaje de Asociados para ahorro
A14: Total de Asociados Activos | B14: 29876
A15: Cantidad de inicial de Asociados de Ahorro | B15: =+B14*B13 -> 0
A16: Composición de los depósitos por rango de Importe
A17: Monto de Depósitos promedio rango 1
A18: Monto de Depósitos promedio rango 2
A19: Monto de Depósitos promedio rango 3
A20: Composición de los depósitos por rango en %
A21: Cantidad de Asociados rango 1
A22: Cantidad de Asociados rango 2
A23: Cantidad de Asociados rango 3
A24: Cantidad de Asociados por rango
A25: Cantidad de Asociados rango 1 | B25: =+B21*$B$15 -> 0
A26: Cantidad de Asociados rango 2 | B26: =+B22*$B$15 -> 0
A27: Cantidad de Asociados rango 3 | B27: =+B23*$B$15 -> 0
A28: CAPTACION DE DEPOSITOS EN PESOS | B28: Monto
A29: Ahorro de Asociados rango 1 | B29: =+B25*B17 -> 0
A30: Ahorro de Asociados rango 2 | B30: =+B26*B18 -> 0
A31: Ahorro de Asociados rango 3 | B31: =+B27*B19 -> 0
A32: Total Captación | B32: =SUM(B29:B31) -> 0
A35: CRECIMIENTO ANUAL DE ASOCIADOS Y CARTERAS | B35: Año 1 | C35: Año 2
A36: Crecimiento anual de Asociados
A37: Crecimiento anual de los Ahorros
A40: Porcentaje de utilización del ahorro captado | B40: 0.8
A42: Tasas de Crecimiento de Cartera y Servicios | B42: Año 1 | C42: Año 2
A43: Ayuda Económica Cartera Nueva | B43: 0.2 | C43: 0.24
A44: Servicios de Turismo | B44: 0.3 | C44: 0.3
A45: Servicio de Orden de Compra | B45: 0.3 | C45: 0.3
A48: Variaciones de los gastos significativos | B48: Año 1 | C48: Año 2
A49: Evolución del crecimiento de los subsidios | B49: 0 | C49: 0
A50: Baja de los intereses bancarios | B50: 0 | C50: 0
...

Sheet Proyección Asociados y Ahorro
A1: PROYECCION DEL CRECIMIENTO DE LOS ASOCIADOS Y LAS CUENTAS DE AHORRO
A3: Concepto | B3: Inicio | C3: MES 1 | D3: MES 2 | E3: MES 3 | F3: MES 4 | G3: MES 5 | H3: MES 6 | I3: MES 7 | J3: MES 8 | K3: MES 9 | L3: MES 10 | M3: MES 11 | N3: MES 12 | O3: MES 13 | P3: MES 14 | Q3: MES 15 | R3: MES 16 | S3: MES 17 | T3: MES 18 | U3: MES 19 | V3: MES 20 | W3: MES 21 | X3: MES 22 | Y3: MES 23 | Z3: MES 24
A4: Cantidad de Asociados | B4: =+'Variables '!B14 -> 29876 | C4: =(B4*('Variables '!$B$36/12))+B4 -> 29876 | D4: =(C4*('Variables '!$B$36/12))+C4 -> 29876 | E4: =(D4*('Variables '!$B$36/12))+D4 -> 29876 | F4: =(E4*('Variables '!$B$36/12))+E4 -> 29876 | G4: =(F4*('Variables '!$B$36/12))+F4 -> 29876 | H4: =(G4*('Variables '!$B$36/12))+G4 -> 29876 | I4: =(H4*('Variables '!$B$36/12))+H4 -> 29876 | J4: =(I4*('Variables '!$B$36/12))+I4 -> 29876 | ... N4: =(M4*('Variables '!$B$36/12))+M4 -> 29876 | O4: =(N4*('Variables '!$C$36/12))+N4 -> 29876 | P4: =(O4*('Variables '!$C$36/12))+O4 -> 29876 | Q4: =(P4*('Variables '!$C$36/12))+P4 -> 29876 | R4: =(Q4*('Variables '!$C$36/12))+Q4 -> 29876 | S4: =(R4*('Variables '!$C$36/12))+R4 -> 29876 | T4: =(S4*('Variables '!$C$36/12))+S4 -> 29876 | U4: =(T4*('Variables '!$C$36/12))+T4 -> 29876 | V4: =(U4*('Variables '!$C$36/12))+U4 -> 29876 | ... Z4: =(Y4*('Variables '!$C$36/12))+Y4 -> 29876
A5: Crecimiento Mensual | C5: =+C4-B4 -> 0 | D5: =+D4-C4 -> 0 | E5: =+E4-D4 -> 0 | F5: =+F4-E4 -> 0 | G5: =+G4-F4 -> 0 | H5: =+H4-G4 -> 0 | I5: =+I4-H4 -> 0 | J5: =+J4-I4 -> 0 | ... Z5: =+Z4-Y4 -> 0
A7: Depósitos de Ahorro | B7: =+'Variables '!B32 -> 0 | C7: =(B7*('Variables '!$B$37/12)+B7) -> 0 | D7: =(C7*('Variables '!$B$37/12)+C7) -> 0 | E7: =(D7*('Variables '!$B$37/12)+D7) -> 0 | F7: =(E7*('Variables '!$B$37/12)+E7) -> 0 | G7: =(F7*('Variables '!$B$37/12)+F7) -> 0 | H7: =(G7*('Variables '!$B$37/12)+G7) -> 0 | I7: =(H7*('Variables '!$B$37/12)+H7) -> 0 | J7: =(I7*('Variables '!$B$37/12)+I7) -> 0 | ... N7: =(M7*('Variables '!$B$37/12)+M7) -> 0 | O7: =(N7*('Variables '!$C$37/12)+N7) -> 0 | P7: =(O7*('Variables '!$C$37/12)+O7) -> 0 | Q7: =(P7*('Variables '!$C$37/12)+P7) -> 0 | R7: =(Q7*('Variables '!$C$37/12)+Q7) -> 0 | S7: =(R7*('Variables '!$C$37/12)+R7) -> 0 | T7: =(S7*('Variables '!$C$37/12)+S7) -> 0 | U7: =(T7*('Variables '!$C$37/12)+T7) -> 0 | V7: =(U7*('Variables '!$C$37/12)+U7) -> 0 | ... Z7: =(Y7*('Variables '!$C$37/12)+Y7) -> 0
A8: Intereses por Depósitos | C8: =+B7*('Variables '!$B$8/12) -> 0 | D8: =+C7*('Variables '!$B$8/12) -> 0 | E8: =+D7*('Variables '!$B$8/12) -> 0 | F8: =+E7*('Variables '!$B$8/12) -> 0 | G8: =+F7*('Variables '!$B$8/12) -> 0 | H8: =+G7*('Variables '!$B$8/12) -> 0 | I8: =+H7*('Variables '!$B$8/12) -> 0 | J8: =+I7*('Variables '!$B$8/12) -> 0 | ... O8: =+N7*('Variables '!$B$8/12) -> 0 | P8: =+O7*('Variables '!$C$8/12) -> #DIV/0! | Q8: =+P7*('Variables '!$C$8/12) -> #DIV/0! | R8: =+Q7*('Variables '!$C$8/12) -> #DIV/0! | S8: =+R7*('Variables '!$C$8/12) -> #DIV/0! | T8: =+S7*('Variables '!$C$8/12) -> #DIV/0! | U8: =+T7*('Variables '!$C$8/12) -> #DIV/0! | V8: =+U7*('Variables '!$C$8/12) -> #DIV/0! | W8: =+V7*('Variables '!$C$8/12) -> #DIV/0! | ... Z8: =+Y7*('Variables '!$C$8/12) -> #DIV/0!
A10: Valor de la Cuota | B10: 80 | C10: =(B10*'Variables '!$B$5)+B10 -> 80 | D10: =+C10 -> 80 | E10: =+D10 -> 80 | F10: =+E10 -> 80 | G10: =+F10 -> 80 | H10: =+G10 -> 80 | I10: =+H10 -> 80 | J10: =+I10 -> 80 | K10: =+J10 -> 80 | ... N10: =+M10 -> 80 | O10: =(N10*'Variables '!$C$5)+N10 -> 80 | P10: =+O10 -> 80 | Q10: =+P10 -> 80 | R10: =+Q10 -> 80 | S10: =+R10 -> 80 | T10: =+S10 -> 80 | U10: =+T10 -> 80 | V10: =+U10 -> 80 | W10: =+V10 -> 80 | ... Z10: =+Y10 -> 80
A11: Ingresos por Cuotas | C11: =+C10*C4 -> 2390080 | D11: =+D10*D4 -> 2390080 | E11: =+E10*E4 -> 2390080 | F11: =+F10*F4 -> 2390080 | G11: =+G10*G4 -> 2390080 | H11: =+H10*H4 -> 2390080 | I11: =+I10*I4 -> 2390080 | J11: =+J10*J4 -> 2390080 | ... Z11: =+Z10*Z4 -> 2390080

Sheet Proyección Aplicación Fondeo
A1: PROYECCION DE LA APLICACIÓN DE RECURSOS A LOS SERVICIOS
A3: Depósitos de Ahorro al Mes 1 | B3: =+'Proyección Asociados y Ahorro'!C7 -> 0
A4: Capacidad Prestable | B4: =+B3*'Variables '!B40 -> 0
A6: Concepto | B6: MES 1 | C6: MES 2 | D6: MES 3 | E6: MES 4 | F6: MES 5 | G6: MES 6 | H6: MES 7 | I6: MES 8 | J6: MES 9 | K6: MES 10 | L6: MES 11 | M6: MES 12 | N6: MES 13 | O6: MES 14 | P6: MES 15 | Q6: MES 16 | R6: MES 17 | S6: MES 18 | T6: MES 19 | U6: MES 20 | V6: MES 21 | W6: MES 22 | X6: MES 23 | Y6: MES 24
A7: Evolución de la capacidad prestable | B7: =+B4 -> 0 | C7: =(B7*('Variables '!$B$43/12))+B7 -> 0 | D7: =(C7*('Variables '!$B$43/12))+C7 -> 0 | E7: =(D7*('Variables '!$B$43/12))+D7 -> 0 | F7: =(E7*('Variables '!$B$43/12))+E7 -> 0 | G7: =(F7*('Variables '!$B$43/12))+F7 -> 0 | H7: =(G7*('Variables '!$B$43/12))+G7 -> 0 | I7: =(H7*('Variables '!$B$43/12))+H7 -> 0 | J7: =(I7*('Variables '!$B$43/12))+I7 -> 0 | ... M7: =(L7*('Variables '!$B$43/12))+L7 -> 0 | N7: =(M7*('Variables '!$C$43/12))+M7 -> 0 | O7: =(N7*('Variables '!$C$43/12))+N7 -> 0 | P7: =(O7*('Variables '!$C$43/12))+O7 -> 0 | Q7: =(P7*('Variables '!$C$43/12))+P7 -> 0 | R7: =(Q7*('Variables '!$C$43/12))+Q7 -> 0 | S7: =(R7*('Variables '!$C$43/12))+R7 -> 0 | T7: =(S7*('Variables '!$C$43/12))+S7 -> 0 | U7: =(T7*('Variables '!$C$43/12))+T7 -> 0 | ... Y7: =(X7*('Variables '!$C$43/12))+X7 -> 0
A8: Cobro de Cuotas Cartera | B8: =158344/24 -> 6597.6667 | C8: =158344/24 -> 6597.6667 | D8: =158344/24 -> 6597.6667 | E8: =158344/24 -> 6597.6667 | F8: =158344/24 -> 6597.6667 | G8: =158344/24 -> 6597.6667 | H8: =158344/24 -> 6597.6667 | I8: =158344/24 -> 6597.6667 | ... Y8: =158344/24 -> 6597.6667
A9: Cobro de Intereses Cartera | B9: =+'Cuadro de Resultados'!D6 -> 55428.458 | C9: =+B9 -> 55428.458 | D9: =+C9 -> 55428.458 | E9: =+D9 -> 55428.458 | F9: =+E9 -> 55428.458 | G9: =+F9 -> 55428.458 | H9: =+G9 -> 55428.458 | I9: =+H9 -> 55428.458 | J9: =+I9 -> 55428.458 | ... Y9: =+X9 -> 55428.458
A10: Capacidad Prestable Total | B10: =SUM(B7:B9) -> 62026.125 | C10: =SUM(C7:C9) -> 62026.125 | D10: =SUM(D7:D9) -> 62026.125 | E10: =SUM(E7:E9) -> 62026.125 | F10: =SUM(F7:F9) -> 62026.125 | G10: =SUM(G7:G9) -> 62026.125 | H10: =SUM(H7:H9) -> 62026.125 | I10: =SUM(I7:I9) -> 62026.125 | ... Y10: =SUM(Y7:Y9) -> 62026.125
A13: Tasa de Servicio Ayuda Económica | B13: =+B10*('Variables '!$B$9/12) -> 0 | C13: =+C10*('Variables '!$B$9/12) -> 0 | D13: =+D10*('Variables '!$B$9/12) -> 0 | E13: =+E10*('Variables '!$B$9/12) -> 0 | F13: =+F10*('Variables '!$B$9/12) -> 0 | G13: =+G10*('Variables '!$B$9/12) -> 0 | H13: =+H10*('Variables '!$B$9/12) -> 0 | I13: =+I10*('Variables '!$B$9/12) -> 0 | ... M13: =+M10*('Variables '!$B$9/12) -> 0 | N13: =+N10*('Variables '!$C$9/12) -> #DIV/0! | O13: =+O10*('Variables '!$C$9/12) -> #DIV/0! | P13: =+P10*('Variables '!$C$9/12) -> #DIV/0! | Q13: =+Q10*('Variables '!$C$9/12) -> #DIV/0! | R13: =+R10*('Variables '!$C$9/12) -> #DIV/0! | S13: =+S10*('Variables '!$C$9/12) -> #DIV/0! | T13: =+T10*('Variables '!$C$9/12) -> #DIV/0! | U13: =+U10*('Variables '!$C$9/12) -> #DIV/0! | ... Y13: =+Y10*('Variables '!$C$9/12) -> #DIV/0!

Sheet Cuadro de Resultados
A1: CUADRO DE RESULTADOS PROYECTADOS
A3: CONCEPTO | B3: Pos.Inicial | C3: Prom. Mes | D3: MES 1 | E3: MES 2 | F3: MES 3 | G3: MES 4 | H3: MES 5 | I3: MES 6 | J3: MES 7 | K3: MES 8 | L3: MES 9 | M3: MES 10 | N3: MES 11 | O3: MES 12 | P3: MES 13 | Q3: MES 14 | R3: MES 15 | S3: MES 16 | T3: MES 17 | U3: MES 18 | V3: MES 19 | W3: MES 20 | X3: MES 21 | Y3: MES 22 | Z3: MES 23 | AA3: MES 24 | AB3: Totales
A4: Resultados Positivos
A5: Cuotas Sociales | B5: 287732.4 | C5: =+B5/12 -> 23977.7 | D5: =(+'Proyección Asociados y Ahorro'!C11)/1000 -> 2390.08 | E5: =(+'Proyección Asociados y Ahorro'!D11)/1000 -> 2390.08 | F5: =(+'Proyección Asociados y Ahorro'!E11)/1000 -> 2390.08 | G5: =(+'Proyección Asociados y Ahorro'!F11)/1000 -> 2390.08 | H5: =(+'Proyección Asociados y Ahorro'!G11)/1000 -> 2390.08 | I5: =(+'Proyección Asociados y Ahorro'!H11)/1000 -> 2390.08 | J5: =(+'Proyección Asociados y Ahorro'!I11)/1000 -> 2390.08 | K5: =(+'Proyección Asociados y Ahorro'!J11)/1000 -> 2390.08 | ... AA5: =(+'Proyección Asociados y Ahorro'!Z11)/1000 -> 2390.08 | AB5: =SUM(D5:AA5) -> 57361.92
A6: Tasa de Servicio Ayuda Económica (SALDO ANT) | B6: 665141.5 | C6: =+B6/12 -> 55428.458 | D6: =+C6 -> 55428.458 | E6: =+D6 -> 55428.458 | F6: =+E6 -> 55428.458 | G6: =+F6 -> 55428.458 | H6: =+G6 -> 55428.458 | I6: =+H6 -> 55428.458 | J6: =+I6 -> 55428.458 | K6: =+J6 -> 55428.458 | ... AA6: =+Z6 -> 55428.458 | AB6: =SUM(D6:AA6) -> 1330283
A7: Tasa de Servicio Ayuda Ec. (CARTERA NUEVA) | D7: =+'Proyección Aplicación Fondeo'!B13/1000 -> 0 | E7: =+'Proyección Aplicación Fondeo'!C13/1000 -> 0 | F7: =+'Proyección Aplicación Fondeo'!D13/1000 -> 0 | G7: =+'Proyección Aplicación Fondeo'!E13/1000 -> 0 | H7: =+'Proyección Aplicación Fondeo'!F13/1000 -> 0 | I7: =+'Proyección Aplicación Fondeo'!G13/1000 -> 0 | J7: =+'Proyección Aplicación Fondeo'!H13/1000 -> 0 | K7: =+'Proyección Aplicación Fondeo'!I13/1000 -> 0 | ... AA7: =+'Proyección Aplicación Fondeo'!Y13/1000 -> #DIV/0! | AB7: =SUM(D7:AA7) -> #DIV/0!
A8: Servicios de Turismo | B8: 144655.83 | C8: =+B8/12 -> 12054.652 | D8: =(C8*('Variables '!$B$44/12))+C8 -> 12356.018 | E8: =(D8*('Variables '!$B$44/12))+D8 -> 12664.919 | F8: =(E8*('Variables '!$B$44/12))+E8 -> 12981.542 | G8: =(F8*('Variables '!$B$44/12))+F8 -> 13306.08 | H8: =(G8*('Variables '!$B$44/12))+G8 -> 13638.732 | I8: =(H8*('Variables '!$B$44/12))+H8 -> 13979.701 | J8: =(I8*('Variables '!$B$44/12))+I8 -> 14329.193 | K8: =(J8*('Variables '!$B$44/12))+J8 -> 14687.423 | ... O8: =(N8*('Variables '!$B$44/12))+N8 -> 16212.167 | P8: =(O8*('Variables '!$C$44/12))+O8 -> 16617.471 | Q8: =(P8*('Variables '!$C$44/12))+P8 -> 17032.908 | R8: =(Q8*('Variables '!$C$44/12))+Q8 -> 17458.731 | S8: =(R8*('Variables '!$C$44/12))+R8 -> 17895.199 | T8: =(S8*('Variables '!$C$44/12))+S8 -> 18342.579 | U8: =(T8*('Variables '!$C$44/12))+T8 -> 18801.143 | V8: =(U8*('Variables '!$C$44/12))+U8 -> 19271.172 | W8: =(V8*('Variables '!$C$44/12))+V8 -> 19752.951 | ... AA8: =(Z8*('Variables '!$C$44/12))+Z8 -> 21803.562 | AB8: =SUM(D8:AA8) -> 399705.31
A9: Servicio de Orden de Compra | B9: 19725.794 | C9: =+B9/12 -> 1643.8162 | D9: =(C9*('Variables '!$B$45/12))+C9 -> 1684.9116 | E9: =(D9*('Variables '!$B$45/12))+D9 -> 1727.0344 | F9: =(E9*('Variables '!$B$45/12))+E9 -> 1770.2102 | G9: =(F9*('Variables '!$B$45/12))+F9 -> 1814.4655 | H9: =(G9*('Variables '!$B$45/12))+G9 -> 1859.8271 | I9: =(H9*('Variables '!$B$45/12))+H9 -> 1906.3228 | J9: =(I9*('Variables '!$B$45/12))+I9 -> 1953.9809 | K9: =(J9*('Variables '!$B$45/12))+J9 -> 2002.8304 | ... O9: =(N9*('Variables '!$B$45/12))+N9 -> 2210.75 | P9: =(O9*('Variables '!$C$45/12))+O9 -> 2266.0188 | Q9: =(P9*('Variables '!$C$45/12))+P9 -> 2322.6692 | R9: =(Q9*('Variables '!$C$45/12))+Q9 -> 2380.736 | S9: =(R9*('Variables '!$C$45/12))+R9 -> 2440.2544 | T9: =(S9*('Variables '!$C$45/12))+S9 -> 2501.2607 | U9: =(T9*('Variables '!$C$45/12))+T9 -> 2563.7923 | V9: =(U9*('Variables '!$C$45/12))+U9 -> 2627.8871 | W9: =(V9*('Variables '!$C$45/12))+V9 -> 2693.5842 | ... AA9: =(Z9*('Variables '!$C$45/12))+Z9 -> 2973.213 | AB9: =SUM(D9:AA9) -> 54505.269
A10: Total de Resultados Positivos | B10: =SUM(B5:B9) -> 1117255.5 | C10: =SUM(C5:C9) -> 93104.626 | D10: =SUM(D5:D9) -> 71859.468 | E10: =SUM(E5:E9) -> 72210.491 | F10: =SUM(F5:F9) -> 72570.29 | G10: =SUM(G5:G9) -> 72939.084 | H10: =SUM(H5:H9) -> 73317.097 | I10: =SUM(I5:I9) -> 73704.561 | ... AA10: =SUM(AA5:AA9) -> #DIV/0! | AB10: =SUM(D10:AA10) -> #DIV/0!
A12: Resultados Negativos
A13: Aportes Inaes (Art. 9) | B13: 3996.2324 | C13: =+B13/12 -> 333.01936 | D13: =+C13+(C13*'Variables '!$B$5) -> 333.01936 | E13: =+D13 -> 333.01936 | F13: =+E13 -> 333.01936 | G13: =+F13 -> 333.01936 | H13: =+G13 -> 333.01936 | I13: =+H13 -> 333.01936 | J13: =+I13 -> 333.01936 | K13: =+J13 -> 333.01936 | L13: =+K13 -> 333.01936 | ... O13: =+N13 -> 333.01936 | P13: =+O13+(O13*'Variables '!$C$5) -> 333.01936 | Q13: =+P13 -> 333.01936 | R13: =+Q13 -> 333.01936 | S13: =+R13 -> 333.01936 | T13: =+S13 -> 333.01936 | U13: =+T13 -> 333.01936 | V13: =+U13 -> 333.01936 | W13: =+V13 -> 333.01936 | X13: =+W13 -> 333.01936 | ... AA13: =+Z13 -> 333.01936 | AB13: =SUM(D13:AA13) -> 7992.4648
A14: Sueldos Y Cargas Sociales | B14: 162000 | C14: =+B14/12 -> 13500 | D14: =(C14+(C14*'Variables '!$B$53))*(1+'Variables '!$B$5) -> 13500 | E14: =+D14 -> 13500 | F14: =+E14 -> 13500 | G14: =+F14 -> 13500 | H14: =+G14 -> 13500 | I14: =+H14 -> 13500 | J14: =+I14 -> 13500 | K14: =+J14 -> 13500 | L14: =+K14 -> 13500 | ... O14: =+N14 -> 13500 | P14: =(O14+(O14*'Variables '!$C$53))*(1+'Variables '!$C$5) -> 13500 | Q14: =+P14 -> 13500 | R14: =+Q14 -> 13500 | S14: =+R14 -> 13500 | T14: =+S14 -> 13500 | U14: =+T14 -> 13500 | V14: =+U14 -> 13500 | W14: =+V14 -> 13500 | X14: =+W14 -> 13500 | ... AA14: =+Z14 -> 13500 | AB14: =SUM(D14:AA14) -> 324000
A15: Otros Beneficios al personal | B15: 13400 | C15: =+B15/12 -> 1116.6667 | D15: =+C15+(C15*'Variables '!$B$5) -> 1116.6667 | E15: =+D15 -> 1116.6667 | F15: =+E15 -> 1116.6667 | G15: =+F15 -> 1116.6667 | H15: =+G15 -> 1116.6667 | I15: =+H15 -> 1116.6667 | J15: =+I15 -> 1116.6667 | K15: =+J15 -> 1116.6667 | L15: =+K15 -> 1116.6667 | ... O15: =+N15 -> 1116.6667 | P15: =+O15+(O15*'Variables '!$C$5) -> 1116.6667 | Q15: =+P15 -> 1116.6667 | R15: =+Q15 -> 1116.6667 | S15: =+R15 -> 1116.6667 | T15: =+S15 -> 1116.6667 | U15: =+T15 -> 1116.6667 | V15: =+U15 -> 1116.6667 | W15: =+V15 -> 1116.6667 | X15: =+W15 -> 1116.6667 | ... AA15: =+Z15 -> 1116.6667 | AB15: =SUM(D15:AA15) -> 26800
A16: Otros Gastos de personal | B16: 631.81678 | C16: =+B16/12 -> 52.651398 | D16: =+C16+(C16*'Variables '!$B$5) -> 52.651398 | E16: =+D16 -> 52.651398 | F16: =+E16 -> 52.651398 | G16: =+F16 -> 52.651398 | H16: =+G16 -> 52.651398 | I16: =+H16 -> 52.651398 | J16: =+I16 -> 52.651398 | K16: =+J16 -> 52.651398 | L16: =+K16 -> 52.651398 | ... O16: =+N16 -> 52.651398 | P16: =+O16+(O16*'Variables '!$C$5) -> 52.651398 | Q16: =+P16 -> 52.651398 | R16: =+Q16 -> 52.651398 | S16: =+R16 -> 52.651398 | T16: =+S16 -> 52.651398 | U16: =+T16 -> 52.651398 | V16: =+U16 -> 52.651398 | W16: =+V16 -> 52.651398 | X16: =+W16 -> 52.651398 | ... AA16: =+Z16 -> 52.651398 | AB16: =SUM(D16:AA16) -> 1263.6336
A17: Seguro | B17: 2500 | C17: =+B17/12 -> 208.33333 | D17: =+C17+(C17*'Variables '!$B$5) -> 208.33333 | E17: =+D17 -> 208.33333 | F17: =+E17 -> 208.33333 | G17: =+F17 -> 208.33333 | H17: =+G17 -> 208.33333 | I17: =+H17 -> 208.33333 | J17: =+I17 -> 208.33333 | K17: =+J17 -> 208.33333 | L17: =+K17 -> 208.33333 | ... O17: =+N17 -> 208.33333 | P17: =+O17+(O17*'Variables '!$C$5) -> 208.33333 | Q17: =+P17 -> 208.33333 | R17: =+Q17 -> 208.33333 | S17: =+R17 -> 208.33333 | T17: =+S17 -> 208.33333 | U17: =+T17 -> 208.33333 | V17: =+U17 -> 208.33333 | W17: =+V17 -> 208.33333 | X17: =+W17 -> 208.33333 | ... AA17: =+Z17 -> 208.33333 | AB17: =SUM(D17:AA17) -> 5000
A18: Honorarios | B18: 46876.294 | C18: =+B18/12 -> 3906.3578 | D18: =+C18+(C18*'Variables '!$B$5) -> 3906.3578 | E18: =+D18 -> 3906.3578 | F18: =+E18 -> 3906.3578 | G18: =+F18 -> 3906.3578 | H18: =+G18 -> 3906.3578 | I18: =+H18 -> 3906.3578 | J18: =+I18 -> 3906.3578 | K18: =+J18 -> 3906.3578 | L18: =+K18 -> 3906.3578 | ... O18: =+N18 -> 3906.3578 | P18: =+O18+(O18*'Variables '!$C$5) -> 3906.3578 | Q18: =+P18 -> 3906.3578 | R18: =+Q18 -> 3906.3578 | S18: =+R18 -> 3906.3578 | T18: =+S18 -> 3906.3578 | U18: =+T18 -> 3906.3578 | V18: =+U18 -> 3906.3578 | W18: =+V18 -> 3906.3578 | X18: =+W18 -> 3906.3578 | ... AA18: =+Z18 -> 3906.3578 | AB18: =SUM(D18:AA18) -> 93752.587
A19: Gastos de Representación | B19: 2193.0464 | C19: =+B19/12 -> 182.75386 | D19: =+C19+(C19*'Variables '!$B$5) -> 182.75386 | E19: =+D19 -> 182.75386 | F19: =+E19 -> 182.75386 | G19: =+F19 -> 182.75386 | H19: =+G19 -> 182.75386 | I19: =+H19 -> 182.75386 | J19: =+I19 -> 182.75386 | K19: =+J19 -> 182.75386 | L19: =+K19 -> 182.75386 | ... O19: =+N19 -> 182.75386 | P19: =+O19+(O19*'Variables '!$C$5) -> 182.75386 | Q19: =+P19 -> 182.75386 | R19: =+Q19 -> 182.75386 | S19: =+R19 -> 182.75386 | T19: =+S19 -> 182.75386 | U19: =+T19 -> 182.75386 | V19: =+U19 -> 182.75386 | W19: =+V19 -> 182.75386 | X19: =+W19 -> 182.75386 | ... AA19: =+Z19 -> 182.75386 | AB19: =SUM(D19:AA19) -> 4386.0928
A20: Gastos Generales de Administración | B20: 34000 | C20: =+B20/12 -> 2833.3333 | D20: =+C20+(C20*'Variables '!$B$5) -> 2833.3333 | E20: =+D20 -> 2833.3333 | F20: =+E20 -> 2833.3333 | G20: =+F20 -> 2833.3333 | H20: =+G20 -> 2833.3333 | I20: =+H20 -> 2833.3333 | J20: =+I20 -> 2833.3333 | K20: =+J20 -> 2833.3333 | L20: =+K20 -> 2833.3333 | ... O20: =+N20 -> 2833.3333 | P20: =+O20+(O20*'Variables '!$C$5) -> 2833.3333 | Q20: =+P20 -> 2833.3333 | R20: =+Q20 -> 2833.3333 | S20: =+R20 -> 2833.3333 | T20: =+S20 -> 2833.3333 | U20: =+T20 -> 2833.3333 | V20: =+U20 -> 2833.3333 | W20: =+V20 -> 2833.3333 | X20: =+W20 -> 2833.3333 | ... AA20: =+Z20 -> 2833.3333 | AB20: =SUM(D20:AA20) -> 68000
A21: Papelería e Imprenta | B21: 22203.046 | C21: =+B21/12 -> 1850.2539 | D21: =+C21+(C21*'Variables '!$B$5) -> 1850.2539 | E21: =+D21 -> 1850.2539 | F21: =+E21 -> 1850.2539 | G21: =+F21 -> 1850.2539 | H21: =+G21 -> 1850.2539 | I21: =+H21 -> 1850.2539 | J21: =+I21 -> 1850.2539 | K21: =+J21 -> 1850.2539 | L21: =+K21 -> 1850.2539 | ... O21: =+N21 -> 1850.2539 | P21: =+O21+(O21*'Variables '!$C$5) -> 1850.2539 | Q21: =+P21 -> 1850.2539 | R21: =+Q21 -> 1850.2539 | S21: =+R21 -> 1850.2539 | T21: =+S21 -> 1850.2539 | U21: =+T21 -> 1850.2539 | V21: =+U21 -> 1850.2539 | W21: =+V21 -> 1850.2539 | X21: =+W21 -> 1850.2539 | ... AA21: =+Z21 -> 1850.2539 | AB21: =SUM(D21:AA21) -> 44406.092
A22: Gastos Cafetería e Higiene Oficina | B22: 2954.971 | C22: =+B22/12 -> 246.24759 | D22: =+C22+(C22*'Variables '!$B$5) -> 246.24759 | E22: =+D22 -> 246.24759 | F22: =+E22 -> 246.24759 | G22: =+F22 -> 246.24759 | H22: =+G22 -> 246.24759 | I22: =+H22 -> 246.24759 | J22: =+I22 -> 246.24759 | K22: =+J22 -> 246.24759 | L22: =+K22 -> 246.24759 | ... O22: =+N22 -> 246.24759 | P22: =+O22+(O22*'Variables '!$C$5) -> 246.24759 | Q22: =+P22 -> 246.24759 | R22: =+Q22 -> 246.24759 | S22: =+R22 -> 246.24759 | T22: =+S22 -> 246.24759 | U22: =+T22 -> 246.24759 | V22: =+U22 -> 246.24759 | W22: =+V22 -> 246.24759 | X22: =+W22 -> 246.24759 | ... AA22: =+Z22 -> 246.24759 | AB22: =SUM(D22:AA22) -> 5909.9421
A23: Servicios Gas, Energía Eléctrica y Teléfono | B23: 25630.185 | C23: =+B23/12 -> 2135.8488 | D23: =+C23+(C23*'Variables '!$B$5) -> 2135.8488 | E23: =+D23 -> 2135.8488 | F23: =+E23 -> 2135.8488 | G23: =+F23 -> 2135.8488 | H23: =+G23 -> 2135.8488 | I23: =+H23 -> 2135.8488 | J23: =+I23 -> 2135.8488 | K23: =+J23 -> 2135.8488 | L23: =+K23 -> 2135.8488 | ... O23: =+N23 -> 2135.8488 | P23: =+O23+(O23*'Variables '!$C$5) -> 2135.8488 | Q23: =+P23 -> 2135.8488 | R23: =+Q23 -> 2135.8488 | S23: =+R23 -> 2135.8488 | T23: =+S23 -> 2135.8488 | U23: =+T23 -> 2135.8488 | V23: =+U23 -> 2135.8488 | W23: =+V23 -> 2135.8488 | X23: =+W23 -> 2135.8488 | ... AA23: =+Z23 -> 2135.8488 | AB23: =SUM(D23:AA23) -> 51260.37
A24: Alquileres | B24: 8570 | C24: =+B24/12 -> 714.16667 | D24: =+C24+(C24*'Variables '!$B$5) -> 714.16667 | E24: =+D24 -> 714.16667 | F24: =+E24 -> 714.16667 | G24: =+F24 -> 714.16667 | H24: =+G24 -> 714.16667 | I24: =+H24 -> 714.16667 | J24: =+I24 -> 714.16667 | K24: =+J24 -> 714.16667 | L24: =+K24 -> 714.16667 | ... O24: =+N24 -> 714.16667 | P24: =+O24+(O24*'Variables '!$C$5) -> 714.16667 | Q24: =+P24 -> 714.16667 | R24: =+Q24 -> 714.16667 | S24: =+R24 -> 714.16667 | T24: =+S24 -> 714.16667 | U24: =+T24 -> 714.16667 | V24: =+U24 -> 714.16667 | W24: =+V24 -> 714.16667 | X24: =+W24 -> 714.16667 | ... AA24: =+Z24 -> 714.16667 | AB24: =SUM(D24:AA24) -> 17140
A25: Gastos Informática | B25: 3750 | C25: =+B25/12 -> 312.5 | D25: =+C25+(C25*'Variables '!$B$52) -> 312.5 | E25: =+D25 -> 312.5 | F25: =+E25 -> 312.5 | G25: =+F25 -> 312.5 | H25: =+G25 -> 312.5 | I25: =+H25 -> 312.5 | J25: =+I25 -> 312.5 | K25: =+J25 -> 312.5 | L25: =+K25 -> 312.5 | ... O25: =+N25 -> 312.5 | P25: =O25+(O25*'Variables '!$C$52) -> 312.5 | Q25: =+P25 -> 312.5 | R25: =+Q25 -> 312.5 | S25: =+R25 -> 312.5 | T25: =+S25 -> 312.5 | U25: =+T25 -> 312.5 | V25: =+U25 -> 312.5 | W25: =+V25 -> 312.5 | X25: =+W25 -> 312.5 | ... AA25: =+Z25 -> 312.5 | AB25: =SUM(D25:AA25) -> 7500
A26: Suscripciones y Publicaciones | B26: 64.81818 | C26: =+B26/12 -> 5.401515 | D26: =+C26+(C26*'Variables '!$B$5) -> 5.401515 | E26: =+D26 -> 5.401515 | F26: =+E26 -> 5.401515 | G26: =+F26 -> 5.401515 | H26: =+G26 -> 5.401515 | I26: =+H26 -> 5.401515 | J26: =+I26 -> 5.401515 | K26: =+J26 -> 5.401515 | L26: =+K26 -> 5.401515 | ... O26: =+N26 -> 5.401515 | P26: =+O26+(O26*'Variables '!$C$5) -> 5.401515 | Q26: =+P26 -> 5.401515 | R26: =+Q26 -> 5.401515 | S26: =+R26 -> 5.401515 | T26: =+S26 -> 5.401515 | U26: =+T26 -> 5.401515 | V26: =+U26 -> 5.401515 | W26: =+V26 -> 5.401515 | X26: =+W26 -> 5.401515 | ... AA26: =+Z26 -> 5.401515 | AB26: =SUM(D26:AA26) -> 129.63636
A27: Alquiler y Mantenimiento Rodados | B27: 12345.44 | C27: =+B27/12 -> 1028.7867 | D27: =+C27+(C27*'Variables '!$B$5) -> 1028.7867 | E27: =+D27 -> 1028.7867 | F27: =+E27 -> 1028.7867 | G27: =+F27 -> 1028.7867 | H27: =+G27 -> 1028.7867 | I27: =+H27 -> 1028.7867 | J27: =+I27 -> 1028.7867 | K27: =+J27 -> 1028.7867 | L27: =+K27 -> 1028.7867 | ... O27: =+N27 -> 1028.7867 | P27: =+O27+(O27*'Variables '!$C$5) -> 1028.7867 | Q27: =+P27 -> 1028.7867 | R27: =+Q27 -> 1028.7867 | S27: =+R27 -> 1028.7867 | T27: =+S27 -> 1028.7867 | U27: =+T27 -> 1028.7867 | V27: =+U27 -> 1028.7867 | W27: =+V27 -> 1028.7867 | X27: =+W27 -> 1028.7867 | ... AA27: =+Z27 -> 1028.7867 | AB27: =SUM(D27:AA27) -> 24690.88
A28: Publicidad y Propaganda | B28: 3456 | C28: =+B28/12 -> 288 | D28: =+C28+(C28*'Variables '!$B$5) -> 288 | E28: =+D28 -> 288 | F28: =+E28 -> 288 | G28: =+F28 -> 288 | H28: =+G28 -> 288 | I28: =+H28 -> 288 | J28: =+I28 -> 288 | K28: =+J28 -> 288 | L28: =+K28 -> 288 | ... O28: =+N28 -> 288 | P28: =+O28+(O28*'Variables '!$C$5) -> 288 | Q28: =+P28 -> 288 | R28: =+Q28 -> 288 | S28: =+R28 -> 288 | T28: =+S28 -> 288 | U28: =+T28 -> 288 | V28: =+U28 -> 288 | W28: =+V28 -> 288 | X28: =+W28 -> 288 | ... AA28: =+Z28 -> 288 | AB28: =SUM(D28:AA28) -> 6912
A29: Amortizaciones de Bienes de Uso | B29: 1662.3031 | C29: =+B29/12 -> 138.52526 | D29: =+C29+(C29*'Variables '!$B$5) -> 138.52526 | E29: =+D29 -> 138.52526 | F29: =+E29 -> 138.52526 | G29: =+F29 -> 138.52526 | H29: =+G29 -> 138.52526 | I29: =+H29 -> 138.52526 | J29: =+I29 -> 138.52526 | K29: =+J29 -> 138.52526 | L29: =+K29 -> 138.52526 | ... O29: =+N29 -> 138.52526 | P29: =+O29+(O29*'Variables '!$C$5) -> 138.52526 | Q29: =+P29 -> 138.52526 | R29: =+Q29 -> 138.52526 | S29: =+R29 -> 138.52526 | T29: =+S29 -> 138.52526 | U29: =+T29 -> 138.52526 | V29: =+U29 -> 138.52526 | W29: =+V29 -> 138.52526 | X29: =+W29 -> 138.52526 | ... AA29: =+Z29 -> 138.52526 | AB29: =SUM(D29:AA29) -> 3324.6062
A30: Donaciones | B30: 336 | C30: =+B30/12 -> 28 | D30: =+C30+(C30*'Variables '!$B$5) -> 28 | E30: =+D30 -> 28 | F30: =+E30 -> 28 | G30: =+F30 -> 28 | H30: =+G30 -> 28 | I30: =+H30 -> 28 | J30: =+I30 -> 28 | K30: =+J30 -> 28 | L30: =+K30 -> 28 | ... O30: =+N30 -> 28 | P30: =+O30+(O30*'Variables '!$C$5) -> 28 | Q30: =+P30 -> 28 | R30: =+Q30 -> 28 | S30: =+R30 -> 28 | T30: =+S30 -> 28 | U30: =+T30 -> 28 | V30: =+U30 -> 28 | W30: =+V30 -> 28 | X30: =+W30 -> 28 | ... AA30: =+Z30 -> 28 | AB30: =SUM(D30:AA30) -> 672
A31: Comisiones e intereses Bancarios | B31: 367754.42 | C31: =+B31/12 -> 30646.202 | D31: =C31-(C31*('Variables '!$B$50/12)) -> 30646.202 | E31: =D31-(D31*('Variables '!$B$50/12)) -> 30646.202 | F31: =E31-(E31*('Variables '!$B$50/12)) -> 30646.202 | G31: =F31-(F31*('Variables '!$B$50/12)) -> 30646.202 | H31: =G31-(G31*('Variables '!$B$50/12)) -> 30646.202 | I31: =H31-(H31*('Variables '!$B$50/12)) -> 30646.202 | J31: =I31-(I31*('Variables '!$B$50/12)) -> 30646.202 | K31: =J31-(J31*('Variables '!$B$50/12)) -> 30646.202 | ... O31: =N31-(N31*('Variables '!$B$50/12)) -> 30646.202 | P31: =O31-(O31*('Variables '!$C$50/12)) -> 30646.202 | Q31: =P31-(P31*('Variables '!$C$50/12)) -> 30646.202 | R31: =Q31-(Q31*('Variables '!$C$50/12)) -> 30646.202 | S31: =R31-(R31*('Variables '!$C$50/12)) -> 30646.202 | T31: =S31-(S31*('Variables '!$C$50/12)) -> 30646.202 | U31: =T31-(T31*('Variables '!$C$50/12)) -> 30646.202 | V31: =U31-(U31*('Variables '!$C$50/12)) -> 30646.202 | W31: =V31-(V31*('Variables '!$C$50/12)) -> 30646.202 | ... AA31: =Z31-(Z31*('Variables '!$C$50/12)) -> 30646.202 | AB31: =SUM(D31:AA31) -> 735508.84
A32: Gastos Bancarios | B32: 44586.469 | C32: =+B32/12 -> 3715.5391 | D32: =+C32+(C32*'Variables '!$B$5) -> 3715.5391 | E32: =+D32 -> 3715.5391 | F32: =+E32 -> 3715.5391 | G32: =+F32 -> 3715.5391 | H32: =+G32 -> 3715.5391 | I32: =+H32 -> 3715.5391 | J32: =+I32 -> 3715.5391 | K32: =+J32 -> 3715.5391 | L32: =+K32 -> 3715.5391 | ... O32: =+N32 -> 3715.5391 | P32: =+O32+(O32*'Variables '!$C$5) -> 3715.5391 | Q32: =+P32 -> 3715.5391 | R32: =+Q32 -> 3715.5391 | S32: =+R32 -> 3715.5391 | T32: =+S32 -> 3715.5391 | U32: =+T32 -> 3715.5391 | V32: =+U32 -> 3715.5391 | W32: =+V32 -> 3715.5391 | X32: =+W32 -> 3715.5391 | ... AA32: =+Z32 -> 3715.5391 | AB32: =SUM(D32:AA32) -> 89172.938
A33: Intereses pagados | B33: 9928.7222 | C33: =+B33/12 -> 827.39352 | D33: 0 | E33: 0 | F33: 0 | G33: 0 | H33: 0 | I33: 0 | J33: 0 | K33: 0 | L33: 0 | M33: 0 | N33: 0 | O33: 0 | P33: 0 | Q33: 0 | R33: 0 | S33: 0 | T33: 0 | U33: 0 | V33: 0 | W33: 0 | X33: 0 | Y33: 0 | Z33: 0 | AA33: 0 | AB33: =SUM(D33:AA33) -> 0
A34: Intereses pagados por los Depósitos de Ahorro | B34: 34562.11 | D34: =(+'Proyección Asociados y Ahorro'!C8)/1000 -> 0 | E34: =(+'Proyección Asociados y Ahorro'!D8)/1000 -> 0 | F34: =(+'Proyección Asociados y Ahorro'!E8)/1000 -> 0 | G34: =(+'Proyección Asociados y Ahorro'!F8)/1000 -> 0 | H34: =(+'Proyección Asociados y Ahorro'!G8)/1000 -> 0 | I34: =(+'Proyección Asociados y Ahorro'!H8)/1000 -> 0 | J34: =(+'Proyección Asociados y Ahorro'!I8)/1000 -> 0 | K34: =(+'Proyección Asociados y Ahorro'!J8)/1000 -> 0 | ... AA34: =(+'Proyección Asociados y Ahorro'!Z8)/1000 -> #DIV/0! | AB34: =SUM(D34:AA34) -> #DIV/0!
A35: Impuesto a los Débitos y Créditos Bancarios. | B35: 3414.2329 | C35: =+B35/12 -> 284.51941 | D35: =+C35+(C35*'Variables '!$B$5) -> 284.51941 | E35: =+D35 -> 284.51941 | F35: =+E35 -> 284.51941 | G35: =+F35 -> 284.51941 | H35: =+G35 -> 284.51941 | I35: =+H35 -> 284.51941 | J35: =+I35 -> 284.51941 | K35: =+J35 -> 284.51941 | L35: =+K35 -> 284.51941 | ... O35: =+N35 -> 284.51941 | P35: =+O35+(O35*'Variables '!$C$5) -> 284.51941 | Q35: =+P35 -> 284.51941 | R35: =+Q35 -> 284.51941 | S35: =+R35 -> 284.51941 | T35: =+S35 -> 284.51941 | U35: =+T35 -> 284.51941 | V35: =+U35 -> 284.51941 | W35: =+V35 -> 284.51941 | X35: =+W35 -> 284.51941 | ... AA35: =+Z35 -> 284.51941 | AB35: =SUM(D35:AA35) -> 6828.4658
A36: Otros Impuestos | B36: 1362.4683 | C36: =+B36/12 -> 113.53903 | D36: =+C36+(C36*'Variables '!$B$5) -> 113.53903 | E36: =+D36 -> 113.53903 | F36: =+E36 -> 113.53903 | G36: =+F36 -> 113.53903 | H36: =+G36 -> 113.53903 | I36: =+H36 -> 113.53903 | J36: =+I36 -> 113.53903 | K36: =+J36 -> 113.53903 | L36: =+K36 -> 113.53903 | ... O36: =+N36 -> 113.53903 | P36: =+O36+(O36*'Variables '!$C$5) -> 113.53903 | Q36: =+P36 -> 113.53903 | R36: =+Q36 -> 113.53903 | S36: =+R36 -> 113.53903 | T36: =+S36 -> 113.53903 | U36: =+T36 -> 113.53903 | V36: =+U36 -> 113.53903 | W36: =+V36 -> 113.53903 | X36: =+W36 -> 113.53903 | ... AA36: =+Z36 -> 113.53903 | AB36: =SUM(D36:AA36) -> 2724.9366
A37: Viáticos y Movilidad | B37: 66023.714 | C37: =+B37/12 -> 5501.9762 | D37: =+C37+(C37*'Variables '!$B$5) -> 5501.9762 | E37: =+D37 -> 5501.9762 | F37: =+E37 -> 5501.9762 | G37: =+F37 -> 5501.9762 | H37: =+G37 -> 5501.9762 | I37: =+H37 -> 5501.9762 | J37: =+I37 -> 5501.9762 | K37: =+J37 -> 5501.9762 | L37: =+K37 -> 5501.9762 | ... O37: =+N37 -> 5501.9762 | P37: =+O37+(O37*'Variables '!$C$5) -> 5501.9762 | Q37: =+P37 -> 5501.9762 | R37: =+Q37 -> 5501.9762 | S37: =+R37 -> 5501.9762 | T37: =+S37 -> 5501.9762 | U37: =+T37 -> 5501.9762 | V37: =+U37 -> 5501.9762 | W37: =+V37 -> 5501.9762 | X37: =+W37 -> 5501.9762 | ... AA37: =+Z37 -> 5501.9762 | AB37: =SUM(D37:AA37) -> 132047.43
A38: Franqueo | B38: 90244.814 | C38: =+B38/12 -> 7520.4012 | D38: =(C38*('Variables '!$B$51)) -> 0 | E38: =+D38 -> 0 | F38: =+E38 -> 0 | G38: =+F38 -> 0 | H38: =+G38 -> 0 | I38: =+H38 -> 0 | J38: =+I38 -> 0 | K38: =+J38 -> 0 | L38: =+K38 -> 0 | ... O38: =+N38 -> 0 | P38: =(O38*'Variables '!$C$51) -> 0 | Q38: =+P38 -> 0 | R38: =+Q38 -> 0 | S38: =+R38 -> 0 | T38: =+S38 -> 0 | U38: =+T38 -> 0 | V38: =+U38 -> 0 | W38: =+V38 -> 0 | X38: =+W38 -> 0 | ... AA38: =+Z38 -> 0 | AB38: =SUM(D38:AA38) -> 0
A39: Gastos de Verificacion de datos Asoc A/E | B39: 80456.67 | C39: =+B39/12 -> 6704.7225 | D39: 0 | E39: 0 | F39: 0 | G39: 0 | H39: 0 | I39: 0 | J39: 0 | K39: 0 | L39: 0 | M39: 0 | N39: 0 | O39: 0 | P39: 0 | Q39: 0 | R39: 0 | S39: 0 | T39: 0 | U39: 0 | V39: 0 | W39: 0 | X39: 0 | Y39: 0 | Z39: 0 | AA39: 0 | AB39: =SUM(D39:AA39) -> 0
A40: Subsidios Pagados a Asociados | B40: 4644.4281 | C40: =+B40/12 -> 387.03568 | D40: =((C40*'Variables '!$B$49)/12)+C40 -> 387.03568 | E40: =((D40*'Variables '!$B$49)/12)+D40 -> 387.03568 | F40: =((E40*'Variables '!$B$49)/12)+E40 -> 387.03568 | G40: =((F40*'Variables '!$B$49)/12)+F40 -> 387.03568 | H40: =((G40*'Variables '!$B$49)/12)+G40 -> 387.03568 | I40: =((H40*'Variables '!$B$49)/12)+H40 -> 387.03568 | J40: =((I40*'Variables '!$B$49)/12)+I40 -> 387.03568 | K40: =((J40*'Variables '!$B$49)/12)+J40 -> 387.03568 | ... O40: =((N40*'Variables '!$B$49)/12)+N40 -> 387.03568 | P40: =((O40*'Variables '!$C$49)/12)+O40 -> 387.03568 | Q40: =((P40*'Variables '!$C$49)/12)+P40 -> 387.03568 | R40: =((Q40*'Variables '!$C$49)/12)+Q40 -> 387.03568 | S40: =((R40*'Variables '!$C$49)/12)+R40 -> 387.03568 | T40: =((S40*'Variables '!$C$49)/12)+S40 -> 387.03568 | U40: =((T40*'Variables '!$C$49)/12)+T40 -> 387.03568 | V40: =((U40*'Variables '!$C$49)/12)+U40 -> 387.03568 | W40: =((V40*'Variables '!$C$49)/12)+V40 -> 387.03568 | ... AA40: =((Z40*'Variables '!$C$49)/12)+Z40 -> 387.03568 | AB40: =SUM(D40:AA40) -> 9288.8562
A41: Servicio de Call Center | B41: 1742.2063 | C41: =+B41/12 -> 145.18386 | D41: =+C41+(C41*'Variables '!$B$5) -> 145.18386 | E41: =+D41 -> 145.18386 | F41: =+E41 -> 145.18386 | G41: =+F41 -> 145.18386 | H41: =+G41 -> 145.18386 | I41: =+H41 -> 145.18386 | J41: =+I41 -> 145.18386 | K41: =+J41 -> 145.18386 | L41: =+K41 -> 145.18386 | ... O41: =+N41 -> 145.18386 | P41: =+O41+(O41*'Variables '!$C$5) -> 145.18386 | Q41: =+P41 -> 145.18386 | R41: =+Q41 -> 145.18386 | S41: =+R41 -> 145.18386 | T41: =+S41 -> 145.18386 | U41: =+T41 -> 145.18386 | V41: =+U41 -> 145.18386 | W41: =+V41 -> 145.18386 | X41: =+W41 -> 145.18386 | ... AA41: =+Z41 -> 145.18386 | AB41: =SUM(D41:AA41) -> 3484.4125
A42: Servicio de Cobranzas | B42: 174.22063 | C42: =+B42/12 -> 14.518386 | D42: =+C42+(C42*'Variables '!$B$5) -> 14.518386 | E42: =+D42 -> 14.518386 | F42: =+E42 -> 14.518386 | G42: =+F42 -> 14.518386 | H42: =+G42 -> 14.518386 | I42: =+H42 -> 14.518386 | J42: =+I42 -> 14.518386 | K42: =+J42 -> 14.518386 | L42: =+K42 -> 14.518386 | ... O42: =+N42 -> 14.518386 | P42: =+O42+(O42*'Variables '!$C$5) -> 14.518386 | Q42: =+P42 -> 14.518386 | R42: =+Q42 -> 14.518386 | S42: =+R42 -> 14.518386 | T42: =+S42 -> 14.518386 | U42: =+T42 -> 14.518386 | V42: =+U42 -> 14.518386 | W42: =+V42 -> 14.518386 | X42: =+W42 -> 14.518386 | ... AA42: =+Z42 -> 14.518386 | AB42: =SUM(D42:AA42) -> 348.44125
...
